Workbook

Sheet README
A1: Test Case Design Sheet v1.1
A2: Project | B2: Playwright QA Automation for Insurance Order Entry Platform (Whole Life), application on port 8081. Submission 2: Test Design.
A3: What changed in v1.1 | B3: Reconciled with: the mentor/learner answers to Q-01..Q-17, the Lab Manual (users, URLs, API key header), and constants read from the application source (routes, config, seed data, markup test ids). All 81 tests and their priorities are kept (Q-16). See Change_Log for details.
A4: Basis codes | B4: M = Lab Manual. S = application source (constants, config, seed data, markup). A = learner answer. D = Functional / Problem documents. V = to verify at first run. Source-derived values are expectations to CONFIRM in the running UI, not a replacement for the business documents.
A5: Black-box note | B5: The Lab Manual says to treat both apps as black boxes. The source was used only for constants and selectors. Expected results still come from the functional documents; any difference found at run time is a finding, not a test change.
A7: Sheets | B7: Test_Cases (81) | Test_Data | Calculators (premium and affordability, live formulas) | Environment_Facts (confirmed facts) | Locator_Map (data-testid per page) | Traceability_Risk | Traceability_SDC | Coverage_Summary | Open_Items | Change_Log
A8: Edit these cells | B8: Yellow cells: Execution status, Defect ID, Defect type, Notes (Test_Cases); Official catalog ID (Traceability_SDC); Status (Open_Items). Blue numbers on Calculators and Coverage_Summary are inputs.
A9: Do not rename | B9: Module names, Risk IDs and SDC IDs are used by COUNTIF formulas; keep them exactly, separated by "; ".
A10: Credentials | B10: Usernames only appear in this workbook. Passwords and the API key are read from .env (INSURANCE_PASSWORD, INSURANCE_API_KEY) and are never written into tests, reports or submissions (Lab Manual section 13).
A11: Example row | B11: Row 2 of Test_Cases (TC-AUTH-001) shows the expected level of detail.
A13: Key definitions
A14: Priority | B14: P1 = covers a P1 risk or is a smoke test; P2 = P2 risk; P3 = lower. "Priority basis" names the risk that sets it (Q-16).
A15: Automation status | B15: Ready = all facts known, build now. Needs confirmation = one item in "Remaining open items" must be checked at first run. Automated / Manual only are set while building.
A16: Defect type (if Fail) | B16: Q-17: report both. Expected seeded (candidate) = matches an SDC row; Unexpected = anything else; plus Automation issue and Environment/data so failures are classified before logging.
A17: UI selectors / API contract | B17: data-testid values that exist in the build, or the API call and its response envelope. Use these instead of guessing locators.
A18: Same-agent rule | B18: The API acts as learner001 unless agent_email is passed. Every UI-vs-API comparison must pass agent_email equal to the logged-in UI user.

Sheet Test_Cases
A1: TC ID | B1: Module | C1: Validation ID | D1: Scenario | E1: Risk ID(s) | F1: Seeded defect candidate(s) | G1: Layer | H1: Test type | I1: Priority | J1: Priority basis | K1: Tags | L1: Preconditions | M1: Test data | N1: Test steps | O1: Expected result | P1: UI selectors / API contract | Q1: Page object / helper | R1: Evidence expectation | S1: Remaining open items | T1: Source basis | U1: Automation status | V1: Execution status | W1: Defect ID | X1: Defect type (if Fail) | Y1: Notes
A2: TC-AUTH-001 | B2: Authentication | C2: AUTH-V01 | D2: Valid agent can log in successfully | E2: R-AUTH-01 | F2: SDC-01 | G2: UI | H2: Smoke | I2: P1 | J2: Smoke test; highest linked risk R-AUTH-01 (score 9) | K2: @smoke @regression @authentication @SDC-01 | L2: Application reachable. No active session (fresh browser context). | M2: {validAgent} = agent.valid@insurance.test (password from .env) | N2: 1. Open /login. 2. Fill login-email-input and login-password-input. 3. Click login-submit-button. | O2: - URL is /dashboard (not /login). - dashboard-page is visible with the agent's applications. - No error alert. | P2: /login: login-email-input, login-password-input, login-submit-button; then dashboard-page | Q2: LoginPage, DashboardPage | R2: Screenshot of dashboard greeting; trace on failure. | T2: M, S | U2: Ready | V2: Not run
A3: TC-AUTH-002 | B3: Authentication | C3: AUTH-V02 | D3: Invalid password displays the correct error message | E3: R-AUTH-05 | G3: UI | H3: Smoke | I3: P1 | J3: Smoke test; highest linked risk R-AUTH-05 (score 4) | K3: @smoke @regression @authentication | L3: No active session. | M3: {validAgent} username + wrong password "Wrong#Pass123" | N3: 1. Open /login. 2. Enter valid username and the wrong password. 3. Click sign in. | O3: - User stays on /login. - Invalid-credentials error is displayed (capture exact text on first run). - No session; /dashboard redirects to /login. | P3: login-form, validation-error-alert / status-alert | Q3: LoginPage | R3: Screenshot of error message. | T3: M, S | U3: Ready | V3: Not run
A4: TC-AUTH-003 | B4: Authentication | C4: AUTH-V03 | D4: Blank username and password show mandatory validation | E4: R-AUTH-05 | G4: UI | H4: Negative | I4: P3 | J4: highest linked risk R-AUTH-05 (score 4) | K4: @regression @authentication | L4: No active session. | M4: Empty username and password | N4: 1. Open /login. 2. Leave both fields empty and click sign in. 3. Repeat with only username filled, then only password filled. | O4: - Field-level mandatory errors appear for each empty field. - User stays on /login. - No successful login; no session created. | P4: login-form (browser "required" or server validation: capture which) | Q4: LoginPage | R4: Screenshot of field-level errors. | T4: D, S | U4: Ready | V4: Not run
A5: TC-AUTH-004 | B5: Authentication | C5: AUTH-V04 | D5: Logout clears the session and redirects to login | E5: R-AUTH-06 | G5: UI | H5: Authorization | I5: P2 | J5: highest linked risk R-AUTH-06 (score 6) | K5: @regression @authentication | L5: Agent is logged in on /dashboard. | M5: {validAgent} | N5: 1. Log in, then store the session cookie value. 2. Click nav-logout-button. 3. Assert redirect to /login. 4. Navigate to /dashboard (and use browser Back). 5. Open a new request context carrying the pre-logout session cookie and GET /dashboard. | O5: - Logout lands on /login. - /dashboard redirects to /login. - The old session cookie no longer gives access (redirect to /login). | P5: nav-logout-button; /login; /dashboard | Q5: LoginPage, DashboardPage, apiClient | R5: Screenshot of /login after back navigation; API status code attached. | T5: S | U5: Ready | V5: Not run
A6: TC-AUTH-005 | B6: Authentication | C6: AUTH-V05 | D6: Direct access to dashboard without login is blocked | E6: R-AUTH-06 | G6: UI | H6: Smoke | I6: P1 | J6: Smoke test; highest linked risk R-AUTH-06 (score 6) | K6: @smoke @regression @authentication | L6: Fresh browser context with no storage state. | M6: None | N6: 1. In a fresh context open /dashboard. 2. Repeat for /applications, /applications/new, /profile, /support. 3. Repeat for /applications/{id}/client using a real application id. | O6: - Each request ends on /login. - No protected content is rendered. | P6: Routes behind auth middleware: /dashboard, /applications, /applications/new, /profile, /support | Q6: LoginPage | R6: Screenshot and final URL for each route. | T6: S | U6: Ready | V6: Not run
A7: TC-AUTH-006 | B7: Authentication | C7: AUTH-V06 | D7: Locked user cannot access the dashboard | E7: R-AUTH-02 | F7: SDC-02 | G7: UI + API | H7: Negative | I7: P2 | J7: highest linked risk R-AUTH-02 (score 6) | K7: @regression @api @authentication @SDC-02 | L7: Seeded locked user exists. | M7: {lockedAgent} = agent.locked@insurance.test with correct password | N7: 1. Sign in through /login as {lockedAgent}. 2. Read the message shown. 3. Try to open /dashboard. 4. POST /api/login with the same credentials. | O7: - Account-locked message (not the generic invalid-password message). Capture exact text. - /dashboard is not accessible. - API returns 403, status "error", message "Account locked", errors.account_status present. | P7: UI /login message; API POST /api/login (X-API-Key) | Q7: LoginPage, apiClient | R7: Screenshot of lock message; API response body. | T7: M, S | U7: Ready | V7: Not run
A8: TC-AUTH-007 | B8: Authentication | C8: AUTH-V07 | D8: Account locks after five failed login attempts | E8: R-AUTH-03 | G8: UI + API | H8: Boundary | I8: P2 | J8: highest linked risk R-AUTH-03 (score 6) | K8: @regression @api @authentication | L8: Spare learner-pool account {disposableAgent} on your own VM (confirm with mentor). DESTRUCTIVE. Lock is time-based (locked_until); run LAST in a serial project. | M8: {disposableAgent} with wrong password x5, then correct password | N8: 1. Attempt 1 to 4 with a wrong password; after each, record the message. 2. Attempt 5 with a wrong password. 3. Attempt 6 with the CORRECT password. 4. Read lock flag through API/DB if available. | O8: - Attempts 1-4: invalid-credentials message, account not locked. - Attempt 5: account locked. - Attempt 6 with the correct password is denied until the lock expires. - Record lock duration seen (locked_until) for the report. | P8: login form; users.failed_login_attempts / locked_until (DB columns) | Q8: LoginPage, apiClient | R8: Screenshot after attempts 4, 5 and 6; run note that user needs reset. | S8: OI-14 | T8: D, S | U8: Needs confirmation | V8: Not run
A9: TC-AUTH-008 | B9: Authentication | C9: AUTH-V08 | D9: Password policy rejects weak passwords | E9: R-AUTH-04 | F9: SDC-03 | G9: UI | H9: Negative | I9: P2 | J9: highest linked risk R-AUTH-04 (score 6) | K9: @regression @authentication @SDC-03 | L9: Logged in as {disposableAgent}. Only REJECTED values are submitted, so the password is never changed. (No API endpoint exists for password change.) | M9: TD-PWD-01 table (rule-by-rule weak values) | N9: 1. Open /change-password. 2. For each weak value in TD-PWD-01 enter it as the new password (and matching confirmation) and submit. 3. Read the message(s). 4. Check the strength indicator for a compliant example without submitting it. | O9: - Every weak value is rejected with the message for the broken rule (12+ chars, upper, lower, digit, one of !@#$%^&*, no email username, no common/sequential pattern, no 3 repeated characters). - Password is unchanged (original still logs in). | P9: /change-password: change-password-current, change-password-new, change-password-confirm, change-password-submit, change-password-strength | Q9: LoginPage, apiClient | R9: Screenshot per rejected value (parameterised report). | T9: S | U9: Ready | V9: Not run
A10: TC-DASH-001 | B10: Dashboard & application summary | C10: DASH-V01 | D10: Dashboard loads after successful login | E10: R-DASH-04 | G10: UI | H10: Smoke | I10: P1 | J10: Smoke test; highest linked risk R-DASH-04 (score 4) | K10: @smoke @regression @dashboard | L10: Valid agent logged in. | M10: {validAgent} | N10: 1. Log in (auth fixture). 2. Open /dashboard. 3. Observe summary cards and application list. | O10: - Summary cards (draft, submitted, under review, approved, requires info) are visible. - dashboard-new-application-button is enabled. - dashboard-applications-table is rendered. | P10: dashboard-page, dashboard-summary-draft/-submitted/-under-review/-approved/-requires-info, dashboard-new-application-button, dashboard-applications-table | Q10: DashboardPage | R10: Screenshot of dashboard. | T10: S | U10: Ready | V10: Not run
A11: TC-DASH-002 | B11: Dashboard & application summary | C11: DASH-V02 | D11: Agent sees only their own applications | E11: R-DASH-01 | G11: UI + API | H11: Authorization | I11: P2 | J11: highest linked risk R-DASH-01 (score 6) | K11: @regression @api @dashboard | L11: Two agents each own at least one application. | M11: {validAgent} (agent.valid) and {agent2} (agent.draft) | N11: 1. Log in as {validAgent}; collect application ids from /applications. 2. Log in as {agent2}; collect ids. 3. Compare the sets. 4. GET /api/applications?agent_email=<each agent> and compare with the UI lists. 5. As {validAgent} open /applications/{id} of an application owned by {agent2}. | O11: - The two id sets do not overlap. - UI list equals API list for each agent (same agent_email as the UI user). - Opening another agent's application in the UI is denied (403). | P11: application-row-*, application-open-{id}; API GET /api/applications?agent_email= | Q11: DashboardPage, apiClient | R11: Both ID lists attached to the report. | T11: S | U11: Ready | V11: Not run
A12: TC-DASH-003 | B12: Dashboard & application summary | C12: DASH-V03 | D12: New agent sees empty application state | E12: R-DASH-04 | G12: UI + API | H12: Functional | I12: P3 | J12: highest linked risk R-DASH-04 (score 4) | K12: @regression @api @dashboard | L12: Seeded new agent with no applications. | M12: {newAgent} = agent.new@insurance.test | N12: 1. Log in as {newAgent}. 2. Observe dashboard. 3. Call GET /api/applications. | O12: - Empty-state message and Start New Application CTA are shown. - Draft and submitted counts are zero. - API returns an empty list. | P12: dashboard-empty-state; GET /api/applications?agent_email=agent.new@insurance.test | Q12: DashboardPage, apiClient | R12: Screenshot of empty state. | T12: M, S | U12: Ready | V12: Not run
A13: TC-DASH-004 | B13: Dashboard & application summary | C13: DASH-V04 | D13: Draft application can be resumed from the dashboard | E13: R-DASH-03 | F13: SDC-16 | G13: UI | H13: Functional | I13: P2 | J13: highest linked risk R-DASH-03 (score 6) | K13: @regression @dashboard @SDC-16 | L13: A draft exists with known client data (created by the test). | M13: Draft with first name QA_<runId>, DOB = today - 40y | N13: 1. Create a draft with client data and save it. 2. Return to /dashboard. 3. Click Resume on that draft row. 4. Inspect the client form. | O13: - The application opened has the same ID as the clicked row. - Previously entered values are present in the form. - Status remains Draft. | P13: application-open-{id}; resume lands on the step stored in current_step | Q13: DashboardPage, ClientInformationPage | R13: Screenshot of resumed form. | T13: S | U13: Ready | V13: Not run
A14: TC-DASH-005 | B14: Dashboard & application summary | C14: DASH-V05 | D14: Application status filter and summary counts work correctly | E14: R-DASH-04 | G14: UI + API | H14: Functional | I14: P3 | J14: highest linked risk R-DASH-04 (score 4) | K14: @regression @api @dashboard | L14: Agent with DRAFT and SUBMITTED applications: use {submittedAgent} (agent.submitted) plus a draft created by the test. Approved is out of scope (Q-15). | M14: {validAgent} | N14: 1. Read the dashboard summary counts for Draft, Submitted, Requires info. 2. If a filter control exists on /dashboard or /applications, apply Draft then Submitted and read the rows; otherwise note "no UI filter". 3. GET /api/applications?agent_email=...&status=DRAFT and =SUBMITTED. 4. Compare. | O14: - Summary counts equal the API counts per status. - Any UI filter shows only rows of the chosen status. - API ?status= returns only that status. - If no UI filter exists, record it as an observation against DASH-V05. | P14: dashboard-summary-*; API GET /api/applications?agent_email=&status=DRAFT|SUBMITTED | Q14: DashboardPage, apiClient | R14: Screenshot per filter state. | S14: OI-15 | T14: S, V | U14: Needs confirmation | V14: Not run
A15: TC-DASH-006 | B15: Dashboard & application summary | C15: DASH-V06 | D15: Dashboard status matches the application status API | E15: R-DASH-02 | F15: SDC-18 | G15: UI + API | H15: Reconciliation | I15: P1 | J15: highest linked risk R-DASH-02 (score 9) | K15: @regression @api @dashboard @SDC-18 | L15: Agent owns at least one Draft and one Submitted application. | M15: {learnerUser} (same account used for UI and agent_email) | N15: 1. Log in as {learnerUser}; read application-status-{id} for each row. 2. GET /api/applications?agent_email=<same learner> and GET /api/applications/{id}/status. 3. Compare per id. | O15: - Dashboard status equals list API status and status API application_status for every id. - Comparison uses the same agent on both sides. | P15: application-status-{id}; GET /api/applications?agent_email=; GET /api/applications/{id}/status | Q15: DashboardPage, apiClient | R15: Table of id / UI status / API status attached. | T15: S | U15: Ready | V15: Not run
A16: TC-CLI-001 | B16: Client / insured information | C16: CLI-V01 | D16: Agent can enter valid insured personal information | E16: R-CLI-03; R-CLI-05 | G16: UI | H16: Smoke | I16: P1 | J16: Smoke test; highest linked risk R-CLI-05 (score 6) | K16: @smoke @regression @client | L16: Logged in as {validAgent}; new application started. | M16: Applicant age 40; gender MALE/FEMALE/NON_BINARY; marital SINGLE/MARRIED/DIVORCED/WIDOWED; all mandatory fields filled | N16: 1. Log in; open /applications/new and click application-create-draft-button. 2. Fill every client field. 3. Click client-save-continue-button. | O16: - Redirect to /applications/{id}/address-contact. - Success message "Client information saved." is shown. - GET /api/applications/{id}/client returns the entered values. | P16: client-first-name-input, client-middle-name-input, client-last-name-input, client-dob-input, client-gender-select, client-marital-status-select, client-nationality-input, client-occupation-input, client-employer-name-input, client-employer-address-input, client-save-continue-button | Q16: DashboardPage, ClientInformationPage | R16: Screenshot of completed form. | T16: S | U16: Ready | V16: Not run
A17: TC-CLI-002 | B17: Client / insured information | C17: CLI-V02 | D17: Mandatory personal fields are validated | E17: R-CLI-03 | G17: UI | H17: Negative | I17: P3 | J17: highest linked risk R-CLI-03 (score 4) | K17: @regression @client | L17: New application on the client step. | M17: Mandatory: first name, last name, DOB, gender, marital status, nationality, occupation, employer name, employer address. Middle name is optional. | N17: 1. Fill all fields with valid data. 2. Clear one mandatory field. 3. Try to continue. 4. Repeat for each mandatory field. | O17: - Inline error appears beside the blank field. - Next is disabled or blocked. - Other fields keep their values. | P17: client-first-name-input, client-middle-name-input, client-last-name-input, client-dob-input, client-gender-select, client-marital-status-select, client-nationality-input, client-occupation-input, client-employer-name-input, client-employer-address-input, client-save-continue-button | Q17: ClientInformationPage | R17: Screenshot per field iteration. | T17: D, S | U17: Ready | V17: Not run
A18: TC-CLI-003 | B18: Client / insured information | C18: CLI-V03 | D18: DOB below 18 years is rejected | E18: R-CLI-01 | F18: SDC-04 | G18: UI | H18: Boundary | I18: P1 | J18: highest linked risk R-CLI-01 (score 9) | K18: @regression @client @SDC-04 | L18: New application on the client step. | M18: DOB = today - 18y + 1 day (age 17y 364d) | N18: 1. Enter the underage DOB. 2. Move focus away from the field. 3. Try to continue. | O18: - Per Functional Modules 3.3 an eligibility error appears at entry; expected text "Client age must be between 18 and 65 years.". - If the app only raises it on review/validate, record WHERE it appears and log it as an observation for SDC-04. | P18: client-dob-input; message "Client age must be between 18 and 65 years." (validation summary) | Q18: ClientInformationPage | R18: Screenshot of eligibility error with DOB visible. | S18: OI-15 | T18: D, S | U18: Needs confirmation | V18: Not run
A19: TC-CLI-004 | B19: Client / insured information | C19: CLI-V04 | D19: DOB above 65 years is rejected | E19: R-CLI-01 | F19: SDC-04 | G19: UI | H19: Boundary | I19: P1 | J19: highest linked risk R-CLI-01 (score 9) | K19: @regression @client @SDC-04 | L19: New application on the client step. | M19: DOB = today - 66y | N19: 1. Enter the DOB. 2. Move focus away. 3. Try to continue. | O19: - Eligibility error "Client age must be between 18 and 65 years." appears at entry (or at the latest in the validation summary: record where). | P19: client-dob-input; message "Client age must be between 18 and 65 years." | Q19: ClientInformationPage | R19: Screenshot of eligibility error. | S19: OI-15 | T19: D, S | U19: Needs confirmation | V19: Not run
A20: TC-CLI-005 | B20: Client / insured information | C20: CLI-V05 | D20: Future date of birth is rejected | E20: R-CLI-02 | F20: SDC-05 | G20: UI | H20: Negative | I20: P2 | J20: highest linked risk R-CLI-02 (score 6) | K20: @regression @client @SDC-05 | L20: New application on the client step. | M20: DOB = today + 1 day; DOB = today + 10y | N20: 1. Enter tomorrow as DOB. 2. Observe validation. 3. Repeat with today + 10 years. 4. Reload and confirm nothing was saved. | O20: - Error "Future date of birth is not allowed." appears for both values. - Nothing is saved (reload shows no future DOB; API GET client shows none). | P20: client-dob-input; message "Future date of birth is not allowed." | Q20: ClientInformationPage | R20: Screenshot of error. | T20: D, S | U20: Ready | V20: Not run
A21: TC-CLI-006 | B21: Client / insured information | C21: CLI-P01 | D21: Age boundary values 18 and 65 are accepted | E21: R-CLI-01 | F21: SDC-04 | G21: UI | H21: Boundary | I21: P1 | J21: highest linked risk R-CLI-01 (score 9) | K21: @regression @client @SDC-04 | L21: New application on the client step. PROPOSED test (not in source). | M21: DOB = today - 18y; DOB = today - 65y | N21: 1. Enter DOB for exactly 18 years. 2. Observe validation and continue. 3. Repeat with exactly 65 years. | O21: - Both DOBs are accepted: the rule is inclusive (error only when age < 18 or > 65). - review-client-calculated-age shows 18 and 65 respectively. | P21: client-dob-input; review-client-calculated-age | Q21: ClientInformationPage | R21: Screenshot for both values. | T21: S | U21: Ready | V21: Not run
A22: TC-CLI-007 | B22: Client / insured information | C22: CLI-P02 | D22: Age is calculated correctly from the date of birth | E22: R-CLI-04 | G22: UI | H22: Boundary | I22: P3 | J22: highest linked risk R-CLI-04 (score 4) | K22: @regression @client | L22: Complete application up to the review page, or read calculated_age through GET /api/applications/{id}. | M22: Birthday today (age n); birthday tomorrow (age n-1); 29 February DOB | N22: 1. Enter each DOB. 2. Read the displayed age. 3. Compare with age computed in the test from system date. | O22: - Displayed/stored age equals the age computed by the test from the system date for each DOB. | P22: review-client-calculated-age (age is displayed on the review page) | Q22: ClientInformationPage | R22: Screenshot per DOB. | T22: S | U22: Ready | V22: Not run
A23: TC-CLI-008 | B23: Client / insured information | C23: CLI-P03 | D23: Name and personal field format validation | E23: R-CLI-03 | G23: UI | H23: Negative | I23: P3 | J23: highest linked risk R-CLI-03 (score 4) | K23: @regression @client | L23: New application on the client step. PROPOSED test. | M23: Names: "12345", "@@@", 101-character string, whitespace only; valid: "Anne-Marie O'Neil" | N23: 1. Enter each invalid value in first and last name. 2. Observe errors. 3. Enter the valid value. | O23: - Invalid values are rejected with an inline error. - The valid hyphenated/apostrophe name is accepted. | P23: client-first-name-input, client-middle-name-input, client-last-name-input, client-dob-input, client-gender-select, client-marital-status-select, client-nationality-input, client-occupation-input, client-employer-name-input, client-employer-address-input, client-save-continue-button | Q23: ClientInformationPage | R23: Screenshot per value. | T23: D, V | U23: Ready | V23: Not run
A24: TC-ADR-001 | B24: Address & contact | C24: CLI-V06 | D24: Same-as-residential copies data to mailing address | E24: R-ADR-01 | G24: UI | H24: Functional | I24: P3 | J24: highest linked risk R-ADR-01 (score 4) | K24: @regression @address | L24: Application on the address and contact step. | M24: Residential: 10 Main St, New York, NY, 10001 | N24: 1. Fill residential address. 2. Tick "same as residential". 3. Compare mailing fields. 4. Edit a residential field. 5. Untick the checkbox. | O24: - Mailing fields equal residential after ticking. - Edit residential then save: mailing behaviour matches what is shown (record whether it follows). - Unticking makes mailing editable. | P24: residential-address-line-1/2-input, residential-city-input, residential-state-province-select, residential-postal-code-input, address-same-as-residential-checkbox, mailing-* (same ids), contact-primary-email-input, contact-mobile-number-input, contact-alternate-phone-input, contact-preferred-mode-select, address-contact-save-continue-button | Q24: AddressContactPage | R24: Screenshot after tick and after edit. | T24: S | U24: Ready | V24: Not run
A25: TC-ADR-002 | B25: Address & contact | C25: CLI-V07a | D25: Invalid email formats are rejected | E25: R-ADR-02 | G25: UI | H25: Negative | I25: P3 | J25: highest linked risk R-ADR-02 (score 4) | K25: @regression @address | L25: Application on the address and contact step. | M25: TD-EMAIL: "abc", "a@b", "a@@b.com", "a b@c.com"; valid "qa.user@example.com" | N25: 1. Enter each invalid email. 2. Observe validation. 3. Enter the valid email. | O25: - Each invalid email shows an error and blocks progression. - Valid email is accepted. | P25: contact-primary-email-input | Q25: AddressContactPage | R25: Screenshot per invalid value. | T25: S | U25: Ready | V25: Not run
A26: TC-ADR-003 | B26: Address & contact | C26: CLI-V07b | D26: Invalid phone formats are rejected | E26: R-ADR-02 | G26: UI | H26: Negative | I26: P3 | J26: highest linked risk R-ADR-02 (score 4) | K26: @regression @address | L26: Application on the address and contact step. | M26: US phone rule: optional +1, area code and exchange start 2-9, 10 digits. Invalid: 123 | (055) 123-4567 | +44 20 7946 0958 | 555-0100. Valid: (212) 555-0147 | +1 212-555-0147 | 2125550147 | N26: 1. Enter each invalid value in mobile and alternate phone. 2. Observe validation. 3. Enter a valid number. | O26: - Each invalid value shows an error. - Valid number is accepted. | P26: contact-mobile-number-input, contact-alternate-phone-input | Q26: AddressContactPage | R26: Screenshot per invalid value. | T26: S | U26: Ready | V26: Not run
A27: TC-ADR-004 | B27: Address & contact | C27: ADR-P01 | D27: Postal code format is validated | E27: R-ADR-02 | G27: UI | H27: Negative | I27: P3 | J27: highest linked risk R-ADR-02 (score 4) | K27: @regression @address | L27: Address step. PROPOSED test. | M27: US ZIP rule: 5 digits or ZIP+4. Invalid: 1234 | 123456 | ABCDE | 12345-12. Valid: 10001 | 10001-1234. State must be a US state/DC code. | N27: 1. Enter each invalid postal code. 2. Observe validation. 3. Enter a valid one. | O27: - Invalid codes are rejected; valid code accepted. | P27: residential-postal-code-input, mailing-postal-code-input, *-state-province-select | Q27: AddressContactPage | R27: Screenshot per value. | T27: S | U27: Ready | V27: Not run
A28: TC-ADR-005 | B28: Address & contact | C28: ADR-P02 | D28: Mailing address is mandatory when not same as residential | E28: R-ADR-03 | G28: UI | H28: Negative | I28: P3 | J28: highest linked risk R-ADR-03 (score 2) | K28: @regression @address | L28: Address step. PROPOSED test. | M28: Valid residential; mailing blank | N28: 1. Fill residential. 2. Leave "same as residential" unticked. 3. Leave mailing blank and try to continue. | O28: - Required mailing fields show errors and progression is blocked. | P28: mailing-* inputs; message "Residential and mailing addresses are required." (validation summary) | Q28: AddressContactPage | R28: Screenshot of errors. | T28: D, S | U28: Ready | V28: Not run
A29: TC-ADR-006 | B29: Address & contact | C29: ADR-P03 | D29: Preferred communication mode is required | E29: R-ADR-03 | G29: UI | H29: Negative | I29: P3 | J29: highest linked risk R-ADR-03 (score 2) | K29: @regression @address | L29: Address step. PROPOSED test. | M29: Options: EMAIL, PHONE, MAIL (Postal Mail) | N29: 1. Fill all contact data but leave preferred mode unselected. 2. Try to continue. 3. Select each available mode in turn. | O29: - Error appears and progression is blocked while unselected. - Each mode, once selected, is accepted. | P29: contact-preferred-mode-select | Q29: AddressContactPage | R29: Screenshot of error. | T29: S | U29: Ready | V29: Not run
A30: TC-KYC-001 | B30: KYC, financial & compliance | C30: CLI-V08 | D30: SSN is masked after entry (all screens and responses) | E30: R-KYC-01 | F30: SDC-07 | G30: UI + API | H30: Negative | I30: P1 | J30: highest linked risk R-KYC-01 (score 9) | K30: @regression @api @kyc @SDC-07 | L30: Application on the KYC step. | M30: ID type SSN; value 123-45-6789 (fake) | N30: 1. Enter the SSN and leave the field. 2. Read the displayed value. 3. Continue, then return to the field. 4. Open the review page and confirmation (if reachable). 5. Inspect network responses carrying the client/KYC data for the full SSN string. | O30: - After save only the last four digits are readable: pattern ******* + 6789 (all characters but the last 4 replaced by *, whitespace removed). - Full SSN is not in page text, screenshots, or API responses (only id_number_masked and a hash are returned). - Q-18 was not answered: this pattern is derived from the app and must be confirmed in the UI. | P30: kyc-id-type-select, kyc-id-number-input, kyc-issue-date-input, kyc-expiry-date-input, financial-annual-income-input, financial-net-worth-input, financial-source-of-funds-select, financial-risk-profile-select, compliance-pep-select, compliance-pep-details-input, compliance-declaration-checkbox, kyc-financial-save-continue-button; masked value also on review page; API GET /api/applications/{id} | Q30: KycFinancialPage, ReviewPage, apiClient | R30: Screenshots of each screen; network response excerpt with SSN redacted. | S30: OI-13 | T30: S, V | U30: Needs confirmation | V30: Not run
A31: TC-KYC-002 | B31: KYC, financial & compliance | C31: CLI-V09 | D31: KYC upload rejects unsupported file type | E31: R-DOC-01 | G31: UI | H31: Negative | I31: P3 | J31: highest linked risk R-DOC-01 (score 4) | K31: @regression @kyc | L31: Documents page. In this build the KYC upload control is on /documents, not on the KYC form. | M31: invalid.exe, invalid.txt (generated); document type KYC_ID | N31: 1. Upload invalid.exe. 2. Upload invalid.txt. 3. Check the document list. | O31: - Message "Unsupported document format. Accepted formats are PDF, JPG, and PNG." is shown for each. - No row appears in documents-table. | P31: /applications/{id}/documents: document-type-select = KYC_ID, document-upload-kyc (file), document-upload-button | Q31: KycFinancialPage, fileUploadHelper | R31: Screenshot of error. | T31: S, M | U31: Ready | V31: Not run
A32: TC-KYC-003 | B32: KYC, financial & compliance | C32: CLI-V10 | D32: PEP = Yes requires additional details | E32: R-KYC-05 | G32: UI | H32: Functional | I32: P2 | J32: highest linked risk R-KYC-05 (score 6) | K32: @regression @kyc | L32: Application on the compliance section. | M32: PEP = Yes with and without details | N32: 1. Select PEP = No and observe. 2. Select PEP = Yes. 3. Leave details blank and try to continue. 4. Enter details and continue. | O32: - Details field is hidden for No and shown for Yes. - Blank details block progression with an error. - Valid details are accepted. | P32: compliance-pep-select (0/1), compliance-pep-details-input | Q32: KycFinancialPage | R32: Screenshot of details field and error. | T32: D, S | U32: Ready | V32: Not run
A33: TC-KYC-004 | B33: KYC, financial & compliance | C33: KYC-P01 | D33: Income versus premium affordability is validated | E33: R-KYC-03 | F33: SDC-08 | G33: UI + API | H33: Negative | I33: P1 | J33: highest linked risk R-KYC-03 (score 9) | K33: @regression @api @kyc @SDC-08 | L33: Client step done. PROPOSED test. | M33: SecureLife (WL_SECURE_BASIC), face 250,000, monthly: annual premium 1,187.50. Income 5,000 (limit 1,000 = 20%) must fail; income 50,000 (limit 10,000) must pass. See Test_Data premium calculator. | N33: 1. Enter a low annual income on the KYC step. 2. Configure a product with a high premium. 3. Run validation / proceed to review. 4. Repeat with adequate income. | O33: - Low-income case: "Premium exceeds affordability threshold." appears on validate/review. - Adequate income: no affordability message. - POST /api/applications/{id}/validate returns the same finding. - Confirm in the UI that the rule compares ANNUAL premium with 20% of annual income. | P33: kyc-id-type-select, kyc-id-number-input, kyc-issue-date-input, kyc-expiry-date-input, financial-annual-income-input, financial-net-worth-input, financial-source-of-funds-select, financial-risk-profile-select, compliance-pep-select, compliance-pep-details-input, compliance-declaration-checkbox, kyc-financial-save-continue-button; message "Premium exceeds affordability threshold." (review/validate) | Q33: KycFinancialPage, ProductConfigurationPage, apiClient | R33: Screenshot of warning; validate API response. | S33: OI-11 | T33: S | U33: Needs confirmation | V33: Not run
A34: TC-KYC-005 | B34: KYC, financial & compliance | C34: KYC-P02 | D34: ID number validation changes with ID type | E34: R-KYC-04 | G34: UI | H34: Negative | I34: P3 | J34: highest linked risk R-KYC-04 (score 4) | K34: @regression @kyc | L34: KYC step. PROPOSED test. | M34: TD-ID: for each ID type, one invalid and one valid sample [V] | N34: 1. Select an ID type. 2. Enter an invalid ID number and observe. 3. Enter a valid number. 4. Switch ID type and observe that rules change. | O34: - Invalid numbers are rejected per type; valid ones accepted. - Changing type re-validates the entered number. | P34: kyc-id-type-select options: SSN, STATE_ID, PASSPORT, DRIVERS_LICENSE; kyc-id-number-input | Q34: KycFinancialPage | R34: Screenshot per ID type. | T34: S | U34: Ready | V34: Not run
A35: TC-KYC-006 | B35: KYC, financial & compliance | C35: KYC-P03 | D35: Incomplete compliance declaration blocks progression | E35: R-KYC-05 | G35: UI + API | H35: Negative | I35: P2 | J35: highest linked risk R-KYC-05 (score 6) | K35: @regression @api @kyc | L35: KYC step. PROPOSED test. | M35: Compliance declaration left unanswered | N35: 1. Complete KYC and financial data but leave the compliance declaration incomplete. 2. Try to continue. 3. Call POST .../validate. 4. Complete the declaration. | O35: - Progression is blocked with an error. - Validate API reports the missing declaration. - After completion progression is allowed. | P35: compliance-declaration-checkbox; message "Compliance declarations must be completed." | Q35: KycFinancialPage, apiClient | R35: Screenshot; validate API response. | T35: S | U35: Ready | V35: Not run
A36: TC-PROD-001 | B36: Product selection & policy config | C36: PROD-V01 | D36: Product catalog displays the expected Whole Life products | E36: R-PROD-05 | G36: UI + API | H36: Smoke | I36: P1 | J36: Smoke test; highest linked risk R-PROD-05 (score 4) | K36: @smoke @regression @api @product | L36: Logged in; client steps completed or /products reachable. | M36: 5 active products: WL_SECURE_BASIC, WL_WEALTH_BUILDER, WL_ELITE_LEGACY, WL_FLEXI_PAY, WL_GUARANTEED_RETURN | N36: 1. Open /products. 2. Count and read product cards and names. 3. Call GET /api/products. 4. Compare. | O36: - 5 product cards, one per code above (UI order: by product name). - Names and codes equal /api/products. | P36: /products: product-card-{code}, product-details-{code}; GET /api/products | Q36: ProductCatalogPage, apiClient | R36: Screenshot of catalog; list of names compared. | T36: S | U36: Ready | V36: Not run
A37: TC-PROD-002 | B37: Product selection & policy config | C37: PROD-V02 | D37: Product details page opens correctly | E37: R-PROD-05; R-PROD-06 | G37: UI | H37: Functional | I37: P3 | J37: highest linked risk R-PROD-06 (score 4) | K37: @regression @product | L37: Catalog visible. | M37: Coverage term options WHOLE_LIFE and TO_AGE_100; payment term in years (1-100) | N37: 1. Click a product. 2. Check URL /products/:productId. 3. Read features, eligibility, coverage limits and benefits. 4. Open payment-term and policy-term options on the configuration step. | O37: - Details page opens with features, eligibility, coverage limits and benefits visible. - Payment and policy term options match the product rules (values from Test Data Guide). | P37: product-detail-page, product-name, product-code, product-features; product-payment-term-select, product-coverage-term-select | Q37: ProductCatalogPage, ProductConfigurationPage | R37: Screenshot of details page. | T37: S | U37: Ready | V37: Not run
A38: TC-PROD-003 | B38: Product selection & policy config | C38: PROD-V03 | D38: Face value below minimum is rejected | E38: R-PROD-02 | G38: UI + API | H38: Boundary | I38: P2 | J38: highest linked risk R-PROD-02 (score 6) | K38: @regression @api @product | L38: Product selected; configuration step. | M38: Face value limits (min/max): SecureLife 100,000/1,000,000; WealthBuilder 150,000/1,500,000; Elite Legacy 500,000/5,000,000; FlexiPay 100,000/1,200,000; Guaranteed Return 200,000/2,000,000. Use SecureLife: 99,999 (reject) and 100,000 (accept); repeat for each product. | N38: 1. Enter face value = minimum - 1. 2. Observe validation. 3. Enter face value = minimum. 4. Repeat through the API if an endpoint exists. | O38: - Below-minimum value shows an error and blocks progression. - Minimum value is accepted. | P38: product-sum-assured-input, product-range-help | Q38: ProductConfigurationPage, apiClient | R38: Screenshot of error. | T38: S | U38: Ready | V38: Not run
A39: TC-PROD-004 | B39: Product selection & policy config | C39: PROD-V04 | D39: Face value above maximum is rejected | E39: R-PROD-02 | G39: UI + API | H39: Boundary | I39: P2 | J39: highest linked risk R-PROD-02 (score 6) | K39: @regression @api @product | L39: Product selected; configuration step. | M39: Face value limits (min/max): SecureLife 100,000/1,000,000; WealthBuilder 150,000/1,500,000; Elite Legacy 500,000/5,000,000; FlexiPay 100,000/1,200,000; Guaranteed Return 200,000/2,000,000. Use SecureLife: 1,000,001 (reject) and 1,000,000 (accept); repeat for each product. | N39: 1. Enter face value = maximum + 1. 2. Observe validation. 3. Enter face value = maximum. | O39: - Above-maximum value shows an error and blocks progression. - Maximum value is accepted. | P39: product-sum-assured-input, product-range-help | Q39: ProductConfigurationPage, apiClient | R39: Screenshot of error. | T39: S | U39: Ready | V39: Not run
A40: TC-PROD-005 | B40: Product selection & policy config | C40: PROD-V05 | D40: Premium recalculates when premium frequency changes | E40: R-PROD-03 | F40: SDC-12 | G40: UI + API | H40: Reconciliation | I40: P1 | J40: highest linked risk R-PROD-03 (score 9) | K40: @regression @api @product @SDC-12 | L40: Product selected with a valid face value. | M40: Formula: annual = face/1000 x product rate; period premium = annual / 12, 4, 2 or 1, rounded to 2 decimals. SecureLife (4.75), face 250,000: 98.96 monthly, 296.88 quarterly, 593.75 semi-annual, 1,187.50 annual (tolerance 0.01). See Test_Data calculator. | N40: 1. Set a face value. 2. Select each frequency in turn and read the premium. 3. Change the face value and read again. 4. Compare each UI premium with the API value for the application. | O40: - Premium changes with each frequency and face value as per the formula. - UI value equals the expected value and the API/total premium after save. | P40: product-premium-frequency-select (MONTHLY, QUARTERLY, SEMI_ANNUAL, ANNUAL), product-current-total-premium, premium-preview-help | Q40: ProductConfigurationPage, apiClient | R40: Table of inputs / UI premium / API premium. | T40: S | U40: Ready | V40: Not run
...

Sheet Test_Data
A1: Data ID | B1: Name / placeholder | C1: Values or generation rule | D1: Used by (validation IDs) | E1: Status
A2: TD-USR-01 | B2: {validAgent} | C2: agent.valid@insurance.test. Primary happy path and regression. Owns seeded DRAFT WL202605170001. (Lab Manual 3.1) | D2: AUTH-V01, V02, V04, DASH-*, API-V08 | E2: Confirmed (M)
A3: TD-USR-02 | B3: {agent2} | C3: agent.draft@insurance.test. Second agent with own draft; used for isolation checks. | D3: DASH-V02, API-V08 | E3: Confirmed (M)
A4: TD-USR-03 | B4: {newAgent} | C4: agent.new@insurance.test. Fresh user with no applications. | D4: DASH-V03 | E4: Confirmed (M)
A5: TD-USR-04 | B5: {submittedAgent} | C5: agent.submitted@insurance.test. Owns SUBMITTED WL202605170003 and REQUIRES_INFO WL202605170004 (seed). | D5: DASH-V05, WF-V04 | E5: Confirmed (M, S)
A6: TD-USR-05 | B6: {lockedAgent} | C6: agent.locked@insurance.test. Dedicated locked user (answer to Q-10). | D6: AUTH-V06, API-P02 | E6: Confirmed (M, A)
A7: TD-USR-06 | B7: {learnerUser} | C7: Your assigned learnerNNN@insurance.test (NNN 001-030). Used for all write flows and the E2E. NOTE: API default agent is learner001; always pass agent_email. | D7: WF-*, DASH-V06, API-* setup | E7: Set in .env (A)
A8: TD-USR-07 | B8: {disposableAgent} | C8: Spare learner-pool account on your own VM, used to lock the account and for password-policy checks. Confirm with mentor; fallback agent.new@insurance.test (then run DASH-V03 first). | D8: AUTH-V07, AUTH-V08 | E8: Confirm with mentor
A9: TD-USR-08 | B9: Out of scope | C9: admin@insurance.test and agent.mfa@insurance.test exist in the seed but are NOT in the Lab Manual; admin and MFA are out of scope (Q-06, Q-15). Do not use unless the mentor says so. | D9: - | E9: Out of scope
A10: TD-DOB-01 | B10: Age 17 (reject) | C10: DOB = today - 18y + 1 day. | D10: CLI-V03, API-V03 | E10: Ready
A11: TD-DOB-02 | B11: Age 18 (accept) | C11: DOB = today - 18y. Rule is inclusive. | D11: CLI-P01 | E11: Ready (S)
A12: TD-DOB-03 | B12: Age 40 (valid) | C12: DOB = today - 40y. | D12: CLI-V01, WF-V03 | E12: Ready
... A33: TD-GEN-01 | B33: Naming convention | C33: Created data uses QA_<runId>; tests change only what they created; seeded records are never edited; no database reset (Lab Manual section 8). | D33: All stateful tests | E33: Rule

Sheet Calculators
A1: Premium and affordability calculators
A2: Formula source: application seed data and premium service constants (S). Annual premium = face value / 1000 x rate; period premium = annual / 12, 4, 2 or 1, rounded to 2 decimals. Confirm against the UI at first run (tolerance 0.01).
A4: Base premium
A5: Product | B5: Face value | C5: Rate per 1,000 | D5: Annual premium | E5: Monthly | F5: Quarterly | G5: Semi-annual | H5: Annual | I5: Check vs seed data
A6: SecureLife (WL_SECURE_BASIC), min | B6: 100000 | C6: 4.75 | D6: =B6/1000*C6 -> 475 | E6: =ROUND(D6/12,2) -> 39.58 | F6: =ROUND(D6/4,2) -> 118.75 | G6: =ROUND(D6/2,2) -> 237.5 | H6: =ROUND(D6,2) -> 475
A7: SecureLife, seed example | B7: 250000 | C7: 4.75 | D7: =B7/1000*C7 -> 1187.5 | E7: =ROUND(D7/12,2) -> 98.96 | F7: =ROUND(D7/4,2) -> 296.88 | G7: =ROUND(D7/2,2) -> 593.75 | H7: =ROUND(D7,2) -> 1187.5 | I7: =IF(E7=98.96,"matches seed monthly 98.96","DIFFERENT") -> matches seed monthly 98.96
A8: WealthBuilder (WL_WEALTH_BUILDER), min | B8: 150000 | C8: 5.35 | D8: =B8/1000*C8 -> 802.5 | E8: =ROUND(D8/12,2) -> 66.88 | F8: =ROUND(D8/4,2) -> 200.63 | G8: =ROUND(D8/2,2) -> 401.25 | H8: =ROUND(D8,2) -> 802.5
A9: WealthBuilder, seed example | B9: 350000 | C9: 5.35 | D9: =B9/1000*C9 -> 1872.5 | E9: =ROUND(D9/12,2) -> 156.04 | F9: =ROUND(D9/4,2) -> 468.13 | G9: =ROUND(D9/2,2) -> 936.25 | H9: =ROUND(D9,2) -> 1872.5 | I9: =IF(F9=468.13,"matches seed quarterly 468.13","DIFFERENT") -> matches seed quarterly 468.13
A10: Elite Legacy (WL_ELITE_LEGACY), min | B10: 500000 | C10: 6.1 | D10: =B10/1000*C10 -> 3050 | E10: =ROUND(D10/12,2) -> 254.17 | F10: =ROUND(D10/4,2) -> 762.5 | G10: =ROUND(D10/2,2) -> 1525 | H10: =ROUND(D10,2) -> 3050
A11: FlexiPay (WL_FLEXI_PAY), min | B11: 100000 | C11: 5 | D11: =B11/1000*C11 -> 500 | E11: =ROUND(D11/12,2) -> 41.67 | F11: =ROUND(D11/4,2) -> 125 | G11: =ROUND(D11/2,2) -> 250 | H11: =ROUND(D11,2) -> 500
A12: Guaranteed Return (WL_GUARANTEED_RETURN), min | B12: 200000 | C12: 5.85 | D12: =B12/1000*C12 -> 1170 | E12: =ROUND(D12/12,2) -> 97.5 | F12: =ROUND(D12/4,2) -> 292.5 | G12: =ROUND(D12/2,2) -> 585 | H12: =ROUND(D12,2) -> 1170
A14: Rider premium
A15: Rider | B15: Coverage | C15: Rate per 1,000 | D15: Annual premium | E15: Monthly | F15: Quarterly | G15: Semi-annual | H15: Annual | I15: Note
A16: RIDER_ADB, coverage = base 250,000 | B16: 250000 | C16: 0.85 | D16: =B16/1000*C16 -> 212.5 | E16: =ROUND(D16/12,2) -> 17.71 | F16: =ROUND(D16/4,2) -> 53.13 | G16: =ROUND(D16/2,2) -> 106.25 | H16: =ROUND(D16,2) -> 212.5 | I16: Seed: agent.valid rider premium 17.71 monthly
A17: RIDER_DISABILITY | B17: 250000 | C17: 1.1 | D17: =B17/1000*C17 -> 275 | E17: =ROUND(D17/12,2) -> 22.92 | F17: =ROUND(D17/4,2) -> 68.75 | G17: =ROUND(D17/2,2) -> 137.5 | H17: =ROUND(D17,2) -> 275
A18: RIDER_TERM_ADDON | B18: 250000 | C18: 1.25 | D18: =B18/1000*C18 -> 312.5 | E18: =ROUND(D18/12,2) -> 26.04 | F18: =ROUND(D18/4,2) -> 78.13 | G18: =ROUND(D18/2,2) -> 156.25 | H18: =ROUND(D18,2) -> 312.5
A19: RIDER_CRITICAL_ILLNESS (max 500,000) | B19: 250000 | C19: 1.6 | D19: =B19/1000*C19 -> 400 | E19: =ROUND(D19/12,2) -> 33.33 | F19: =ROUND(D19/4,2) -> 100 | G19: =ROUND(D19/2,2) -> 200 | H19: =ROUND(D19,2) -> 400
A20: RIDER_HOSPITAL_CASH (fixed, max 100,000) | B20: 100000 | C20: 0.65 | D20: =B20/1000*C20 -> 65 | E20: =ROUND(D20/12,2) -> 5.42 | F20: =ROUND(D20/4,2) -> 16.25 | G20: =ROUND(D20/2,2) -> 32.5 | H20: =ROUND(D20,2) -> 65
A22: Affordability rule
A23: Threshold (% of annual income) | B23: 20 | C23: Source: app config DEMO_AFFORDABILITY_PERCENTAGE = 20 (S). Confirm that annual premium is the compared value.
A24: Case | B24: Annual income | C24: Limit | D24: Annual premium | E24: Result | I24: Expected message
A25: Low income, SecureLife 250k monthly | B25: 5000 | C25: =B25*$B$23/100 -> 1000 | D25: =D7 -> 1187.5 | E25: =IF(D25>C25,"EXCEEDS","OK") -> EXCEEDS | I25: =IF(E25="EXCEEDS","Premium exceeds affordability threshold.","none") -> Premium exceeds affordability threshold.
A26: Adequate income, same policy | B26: 50000 | C26: =B26*$B$23/100 -> 10000 | D26: =D7 -> 1187.5 | E26: =IF(D26>C26,"EXCEEDS","OK") -> OK | I26: =IF(E26="EXCEEDS","Premium exceeds affordability threshold.","none") -> none
A27: Low income, Elite Legacy 500k | B27: 10000 | C27: =B27*$B$23/100 -> 2000 | D27: =D10 -> 3050 | E27: =IF(D27>C27,"EXCEEDS","OK") -> EXCEEDS | I27: =IF(E27="EXCEEDS","Premium exceeds affordability threshold.","none") -> Premium exceeds affordability threshold.
A30: Blue = input. Black = formula. Change the inputs to build extra test data; expected values update.

Sheet Environment_Facts
A1: Environment facts (replaces assumptions with sources)
A2: Sources: M = Lab Manual v1.0, A = learner answers, S = application source, V = verify in UI. Passwords and the API key are NOT recorded here (see .env).
A4: 1. Access
A5: Item | B5: Value | C5: Note | E5: Source
A6: Insurance app | B6: http://<vm-ip>:8081/login | C6: Q-01 answered: port 8081. Env: INSURANCE_BASE_URL | E6: M, A
A7: FinServe app | B7: http://<vm-ip>:8082/login | C7: Different project, not used here | E7: M
A8: API base | B8: http://<vm-ip>:8081/api | C8: Header X-API-Key from .env (INSURANCE_API_KEY). GET /api/health is public. | E8: M, S
A9: Platform | B9: Linux combined lab instance | C9: Manual v1.0 says Linux; the earlier Quick Start Manual described a Windows VM with C:\qa-lab. Confirm which applies to your VM. | E9: M, V
A10: Browsers | B10: Chromium default; Firefox and WebKit configurable | C10: Q-12: playwright.config projects selected by env BROWSERS (default chromium). | E10: A
A11: Workers | B11: Start with 1 worker | C11: VM is dedicated (Q-14) but earlier assignments showed concurrency artifacts under load; raise workers only for read-only suites. | E11: A, V
A12: Session lifetime | B12: 120 minutes | C12: Session timeout testing is out of scope (Q-11). | E12: S, A
A13: Database | B13: MySQL (per app config); .sql dump found in db-dumps | C13: Read access still to be confirmed; do not run resets (Manual section 8). | E13: S, A
A15: 2. Seed users (usernames only; password and key in .env)
A16: Account | B16: Use | C16: Seed data / note | E16: Source
A17: agent.valid@insurance.test | B17: Primary happy path | C17: Seeded DRAFT WL202605170001 (step BENEFICIARIES) | E17: M, S
A18: agent.new@insurance.test | B18: Fresh user | C18: No applications | E18: M, S
A19: agent.draft@insurance.test | B19: Draft scenario | C19: Seeded DRAFT WL202605170002 (step DOCUMENTS) | E19: M, S
A20: agent.submitted@insurance.test | B20: Submitted scenario | C20: SUBMITTED WL202605170003; REQUIRES_INFO WL202605170004 | E20: M, S
A21: agent.locked@insurance.test | B21: Locked login | C21: account_status LOCKED | E21: M, S
A22: learner001..learner030@insurance.test | B22: Assigned learner pool | C22: Use your assigned account for write flows | E22: M
A24: 3. API contract (from source)
A25: Topic | B25: Fact | C25: Test impact | E25: Source
A26: Authentication | B26: Static X-API-Key. Missing/wrong key -> 401 {"status":"error","message":"Unauthorized"}. No per-user token. | C26: API-V02, setup helper | E26: S
A27: Agent context | B27: agent_email (or user_id) selects the agent; DEFAULT is learner001@insurance.test. | C27: Always pass agent_email equal to the UI user | E27: S
A28: Envelope | B28: Success {status:"success", message, data}; error {status:"error", message, errors} | C28: Assertion helper | E28: S
A29: POST /api/login | B29: 200 "Login validated successfully" with user fields; 401 "Invalid credentials"; 403 "Account locked"; 422 blank | C29: API-P02, AUTH-V06 | E29: S
A30: POST /api/applications | B30: 201 "Draft application created" (status DRAFT, step CLIENT, MONTHLY, WHOLE_LIFE) | C30: Fast setup for UI tests (OI-05 closed) | E30: S
A31: Other endpoints | B31: GET /applications, /applications/{id}, /{id}/client, /{id}/beneficiaries, /{id}/status; POST /{id}/client, address-contact, kyc-financial, product, riders, beneficiaries, documents, validate, submit; GET /products, /products/{id}, /riders | C31: API-V01..V08, P01, P02 | E31: S
A32: Validate / submit errors | B32: 422 "Validation failed" with errors per section | C32: API-V04, V05, VAL-V03 | E32: S
A33: Status payload | B33: application_id, application_reference_number, application_status, current_step, status_history[] | C33: API-V06, WF-V07 | E33: S
A35: 4. Business limits and rules
A36: Rule | B36: Value | C36: Message / note | E36: Source
A37: Client age | B37: 18 to 65 inclusive | C37: "Client age must be between 18 and 65 years." | E37: A, S
A38: Future DOB | B38: Not allowed | C38: "Future date of birth is not allowed." | E38: S
A39: Max riders | B39: 4 per application | C39: Message to capture | E39: S
A40: Affordability | B40: Annual premium <= 20% of annual income | C40: "Premium exceeds affordability threshold." | E40: S, V
A41: Documents | B41: PDF, JPG, PNG; max 5 MB; required type KYC_ID; types KYC_ID, ADDRESS_PROOF, INCOME_PROOF, OTHER | C41: "Unsupported document format. Accepted formats are PDF, JPG, and PNG." / "Document size exceeds the allowed limit." / "KYC ID document upload is required." | E41: S
A42: Beneficiaries | B42: Primary total exactly 100%; at least one primary; minor needs guardian | C42: "Primary beneficiary allocation must total exactly 100%." / "At least one primary beneficiary is required." / "Guardian details are required for minor beneficiaries." | E42: S
A43: Password policy | B43: 12+ chars; upper; lower; digit; one of !@#$%^&*; no email username; no common/sequential pattern; no 3 repeated characters | C43: Rule-specific messages, e.g. "Password must be at least 12 characters." | E43: S
A44: SSN / ID masking | B44: Characters except last 4 replaced by *; stored masked plus hash | C44: Q-18 unanswered: derived, confirm in UI | E44: S, V
...

Sheet Traceability_Risk
A1: Risk ID | B1: Module | C1: Risk | D1: Priority | E1: Seeded defect | F1: Layers | G1: Planned tests (doc 04) | H1: Test cases linked (live) | I1: Linked test cases (generated list) | J1: Coverage type | K1: Coverage status
A2: R-AUTH-01 | B2: Authentication | C2: Valid agent cannot log in after an authentication change; every journey is blocked. | D2: P1 | E2: SDC-01 | F2: UI · API | G2: AUTH-V01, API-P02 | H2: =COUNTIF(Test_Cases!$E$2:$E$200,"*"&A2&"*") -> 2 | I2: TC-AUTH-001, TC-API-010 | J2: Test cases | K2: =IF(H2>0,"Covered",IF(J2="Test cases","GAP - add test","Addressed outside test cases")) -> Covered
A3: R-AUTH-02 | B3: Authentication | C3: Locked agent sees a wrong or misleading message, or reaches the dashboard. | D3: P2 | E3: SDC-02 | F3: UI · API · DB | G3: AUTH-V06 | H3: =COUNTIF(Test_Cases!$E$2:$E$200,"*"&A3&"*") -> 2 | I3: TC-AUTH-006, TC-API-010 | J3: Test cases | K3: =IF(H3>0,"Covered",IF(J3="Test cases","GAP - add test","Addressed outside test cases")) -> Covered
A4: R-AUTH-03 | B4: Authentication | C4: Account does not lock after five failed attempts (or locks early/late). | D4: P2 | F4: UI · API · DB | G4: AUTH-V07 | H4: =COUNTIF(Test_Cases!$E$2:$E$200,"*"&A4&"*") -> 1 | I4: TC-AUTH-007 | J4: Test cases | K4: =IF(H4>0,"Covered",IF(J4="Test cases","GAP - add test","Addressed outside test cases")) -> Covered
A5: R-AUTH-04 | B5: Authentication | C5: Password policy inconsistent: weak passwords accepted, or UI and API rules differ. | D5: P2 | E5: SDC-03 | F5: UI · API | G5: AUTH-V08 | H5: =COUNTIF(Test_Cases!$E$2:$E$200,"*"&A5&"*") -> 1 | I5: TC-AUTH-008 | J5: Test cases | K5: =IF(H5>0,"Covered",IF(J5="Test cases","GAP - add test","Addressed outside test cases")) -> Covered
A6: R-AUTH-05 | B6: Authentication | C6: Invalid-password and blank-field messages are wrong or missing. | D6: P3 | F6: UI | G6: AUTH-V02, AUTH-V03 | H6: =COUNTIF(Test_Cases!$E$2:$E$200,"*"&A6&"*") -> 2 | I6: TC-AUTH-002, TC-AUTH-003 | J6: Test cases | K6: =IF(H6>0,"Covered",IF(J6="Test cases","GAP - add test","Addressed outside test cases")) -> Covered
A7: R-AUTH-06 | B7: Authentication | C7: Session survives logout, or protected routes and APIs are reachable without login. | D7: P2 | F7: UI · API | G7: AUTH-V04, AUTH-V05, API-V02 | H7: =COUNTIF(Test_Cases!$E$2:$E$200,"*"&A7&"*") -> 3 | I7: TC-AUTH-004, TC-AUTH-005, TC-API-002 | J7: Test cases | K7: =IF(H7>0,"Covered",IF(J7="Test cases","GAP - add test","Addressed outside test cases")) -> Covered
A8: R-AUTH-07 | B8: Authentication | C8: MFA/OTP flow cannot be automated reliably (unknown simulation mechanism). | D8: P3 | F8: UI | G8: Exploratory, AUTH extension | H8: =COUNTIF(Test_Cases!$E$2:$E$200,"*"&A8&"*") -> 0 | J8: Out of scope (Q-06) | K8: =IF(H8>0,"Covered",IF(J8="Test cases","GAP - add test","Addressed outside test cases")) -> Addressed outside test cases
A9: R-DASH-01 | B9: Dashboard | C9: Agent sees another agent's applications (data isolation breach). | D9: P2 | F9: UI · API · DB | G9: DASH-V02, API-V08 | H9: =COUNTIF(Test_Cases!$E$2:$E$200,"*"&A9&"*") -> 2 | I9: TC-DASH-002, TC-API-008 | J9: Test cases | K9: =IF(H9>0,"Covered",IF(J9="Test cases","GAP - add test","Addressed outside test cases")) -> Covered
A10: R-DASH-02 | B10: Dashboard | C10: Dashboard status differs from backend / detail-page status. | D10: P1 | E10: SDC-18 | F10: UI · API · DB | G10: DASH-V06, WF-V07, API-V06 | H10: =COUNTIF(Test_Cases!$E$2:$E$200,"*"&A10&"*") -> 4 | I10: TC-DASH-006, TC-WF-006, TC-WF-007, TC-API-006 | J10: Test cases | K10: =IF(H10>0,"Covered",IF(J10="Test cases","GAP - add test","Addressed outside test cases")) -> Covered
A11: R-DASH-03 | B11: Dashboard | C11: Resume opens a wrong or blank application. | D11: P2 | E11: SDC-16 | F11: UI · DB | G11: DASH-V04 | H11: =COUNTIF(Test_Cases!$E$2:$E$200,"*"&A11&"*") -> 1 | I11: TC-DASH-004 | J11: Test cases | K11: =IF(H11>0,"Covered",IF(J11="Test cases","GAP - add test","Addressed outside test cases")) -> Covered
A12: R-DASH-04 | B12: Dashboard | C12: Status filters return wrong rows; new-agent empty state broken. | D12: P3 | F12: UI | G12: DASH-V03, DASH-V05 | H12: =COUNTIF(Test_Cases!$E$2:$E$200,"*"&A12&"*") -> 3 | I12: TC-DASH-001, TC-DASH-003, TC-DASH-005 | J12: Test cases | K12: =IF(H12>0,"Covered",IF(J12="Test cases","GAP - add test","Addressed outside test cases")) -> Covered
A13: R-CLI-01 | B13: Client information | C13: Age eligibility (18-65) not enforced, or boundary off by one. | D13: P1 | E13: SDC-04 | F13: UI · API | G13: CLI-V03, CLI-V04, CLI-P01, API-V03 | H13: =COUNTIF(Test_Cases!$E$2:$E$200,"*"&A13&"*") -> 4 | I13: TC-CLI-003, TC-CLI-004, TC-CLI-006, TC-API-003 | J13: Test cases | K13: =IF(H13>0,"Covered",IF(J13="Test cases","GAP - add test","Addressed outside test cases")) -> Covered
A14: R-CLI-02 | B14: Client information | C14: Future date of birth accepted and persisted. | D14: P2 | E14: SDC-05 | F14: UI · API · DB | G14: CLI-V05, API-V03 | H14: =COUNTIF(Test_Cases!$E$2:$E$200,"*"&A14&"*") -> 2 | I14: TC-CLI-005, TC-API-003 | J14: Test cases | K14: =IF(H14>0,"Covered",IF(J14="Test cases","GAP - add test","Addressed outside test cases")) -> Covered
A15: R-CLI-03 | B15: Client information | C15: Mandatory personal fields can be left blank. | D15: P3 | F15: UI · API | G15: CLI-V02 | H15: =COUNTIF(Test_Cases!$E$2:$E$200,"*"&A15&"*") -> 3 | I15: TC-CLI-001, TC-CLI-002, TC-CLI-008 | J15: Test cases | K15: =IF(H15>0,"Covered",IF(J15="Test cases","GAP - add test","Addressed outside test cases")) -> Covered
A16: R-CLI-04 | B16: Client information | C16: Age calculation wrong around birthdays, leap years or timezone. | D16: P3 | F16: UI | G16: CLI-P02 | H16: =COUNTIF(Test_Cases!$E$2:$E$200,"*"&A16&"*") -> 1 | I16: TC-CLI-007 | J16: Test cases | K16: =IF(H16>0,"Covered",IF(J16="Test cases","GAP - add test","Addressed outside test cases")) -> Covered
A17: R-CLI-05 | B17: Client information | C17: Saved client data differs between UI and API/database after save. | D17: P2 | F17: UI · API · DB | G17: CLI-V01, API client GET | H17: =COUNTIF(Test_Cases!$E$2:$E$200,"*"&A17&"*") -> 1 | I17: TC-CLI-001 | J17: Test cases | K17: =IF(H17>0,"Covered",IF(J17="Test cases","GAP - add test","Addressed outside test cases")) -> Covered
A18: R-ADR-01 | B18: Address & contact | C18: Same-as-residential copies wrongly or goes stale after later edits. | D18: P3 | F18: UI | G18: CLI-V06 | H18: =COUNTIF(Test_Cases!$E$2:$E$200,"*"&A18&"*") -> 1 | I18: TC-ADR-001 | J18: Test cases | K18: =IF(H18>0,"Covered",IF(J18="Test cases","GAP - add test","Addressed outside test cases")) -> Covered
A19: R-ADR-02 | B19: Address & contact | C19: Invalid email, phone or postal code accepted. | D19: P3 | F19: UI · API | G19: CLI-V07, ADR-P01 | H19: =COUNTIF(Test_Cases!$E$2:$E$200,"*"&A19&"*") -> 3 | I19: TC-ADR-002, TC-ADR-003, TC-ADR-004 | J19: Test cases | K19: =IF(H19>0,"Covered",IF(J19="Test cases","GAP - add test","Addressed outside test cases")) -> Covered
A20: R-ADR-03 | B20: Address & contact | C20: Mailing address or preferred communication mode not enforced. | D20: P3 | F20: UI | G20: ADR-P02, ADR-P03 | H20: =COUNTIF(Test_Cases!$E$2:$E$200,"*"&A20&"*") -> 2 | I20: TC-ADR-005, TC-ADR-006 | J20: Test cases | K20: =IF(H20>0,"Covered",IF(J20="Test cases","GAP - add test","Addressed outside test cases")) -> Covered
A21: R-KYC-01 | B21: KYC & compliance | C21: SSN / ID shown unmasked on entry, review, confirmation or in API payload. | D21: P1 | E21: SDC-07 | F21: UI · API · DB | G21: CLI-V08 | H21: =COUNTIF(Test_Cases!$E$2:$E$200,"*"&A21&"*") -> 1 | I21: TC-KYC-001 | J21: Test cases | K21: =IF(H21>0,"Covered",IF(J21="Test cases","GAP - add test","Addressed outside test cases")) -> Covered
